2021-12-04 03:36:31.385936: I tensorflow/stream_executor/cuda/cuda_dnn.cc:366] Loaded cuDNN version 8100
2021-12-04 03:36:32.128099: I tensorflow/stream_executor/cuda/cuda_blas.cc:1774] TensorFloat-32 will be used for the matrix multiplication. This will only be logged once.
   2/1633 [..............................] - ETA: 9:23 - train_loss: 98.3894























































































































































































































































































1633/1633 [==============================] - 570s 349ms/step - train_loss: 88.8709





























270/279 [===========================>..] - ETA: 2s - valid_loss: 91.8486
279/279 [==============================] - 60s 215ms/step - valid_loss: 91.7353 - train_loss: 88.8709 - val_loss: 91.7353
The validation loss improved from 26968.47265625 to 91.73526763916016.                 Saving model Model.h5












































 251/1633 [===>..........................] - ETA: 8:07 - train_loss: 90.9228
Traceback (most recent call last):
  File "train.py", line 40, in <module>
    train(model, training_data_generator, validation_data_generator, 100,\
  File "/media/avidbeam/workspace/Abdelrahman_Workspace/Project_Codes/Synergy/utils/custom_fit.py", line 30, in train
    train_loss = train_batch(X_batch,\
  File "/media/avidbeam/workspace/Abdelrahman_Workspace/Project_Codes/Synergy/utils/custom_fit.py", line 64, in train_batch
    y_pred = model(X, training=True)
  File "/home/avidbeam/.virtualenvs/TensorFlow_2/lib/python3.8/site-packages/keras/utils/traceback_utils.py", line 64, in error_handler
    return fn(*args, **kwargs)
  File "/home/avidbeam/.virtualenvs/TensorFlow_2/lib/python3.8/site-packages/keras/engine/base_layer.py", line 1083, in __call__
    outputs = call_fn(inputs, *args, **kwargs)
  File "/home/avidbeam/.virtualenvs/TensorFlow_2/lib/python3.8/site-packages/keras/utils/traceback_utils.py", line 92, in error_handler
    return fn(*args, **kwargs)
  File "/media/avidbeam/workspace/Abdelrahman_Workspace/Project_Codes/Synergy/model/synergy.py", line 56, in call
    X = self.mobileNet(batch_images)
  File "/home/avidbeam/.virtualenvs/TensorFlow_2/lib/python3.8/site-packages/keras/utils/traceback_utils.py", line 64, in error_handler
    return fn(*args, **kwargs)
  File "/home/avidbeam/.virtualenvs/TensorFlow_2/lib/python3.8/site-packages/keras/engine/base_layer.py", line 1083, in __call__
    outputs = call_fn(inputs, *args, **kwargs)
  File "/home/avidbeam/.virtualenvs/TensorFlow_2/lib/python3.8/site-packages/keras/utils/traceback_utils.py", line 92, in error_handler
    return fn(*args, **kwargs)
  File "/home/avidbeam/.virtualenvs/TensorFlow_2/lib/python3.8/site-packages/keras/engine/functional.py", line 451, in call
    return self._run_internal_graph(
  File "/home/avidbeam/.virtualenvs/TensorFlow_2/lib/python3.8/site-packages/keras/engine/functional.py", line 589, in _run_internal_graph
    outputs = node.layer(*args, **kwargs)
  File "/home/avidbeam/.virtualenvs/TensorFlow_2/lib/python3.8/site-packages/keras/utils/traceback_utils.py", line 64, in error_handler
    return fn(*args, **kwargs)
  File "/home/avidbeam/.virtualenvs/TensorFlow_2/lib/python3.8/site-packages/keras/engine/base_layer.py", line 1083, in __call__
    outputs = call_fn(inputs, *args, **kwargs)
  File "/home/avidbeam/.virtualenvs/TensorFlow_2/lib/python3.8/site-packages/keras/utils/traceback_utils.py", line 92, in error_handler
    return fn(*args, **kwargs)
  File "/home/avidbeam/.virtualenvs/TensorFlow_2/lib/python3.8/site-packages/keras/layers/convolutional.py", line 246, in call
    outputs = self.convolution_op(inputs, self.kernel)
  File "/home/avidbeam/.virtualenvs/TensorFlow_2/lib/python3.8/site-packages/keras/layers/convolutional.py", line 231, in convolution_op
    return tf.nn.convolution(
  File "/home/avidbeam/.virtualenvs/TensorFlow_2/lib/python3.8/site-packages/tensorflow/python/util/traceback_utils.py", line 150, in error_handler
    return fn(*args, **kwargs)
  File "/home/avidbeam/.virtualenvs/TensorFlow_2/lib/python3.8/site-packages/tensorflow/python/util/dispatch.py", line 1096, in op_dispatch_handler
    return dispatch_target(*args, **kwargs)
  File "/home/avidbeam/.virtualenvs/TensorFlow_2/lib/python3.8/site-packages/tensorflow/python/ops/nn_ops.py", line 1152, in convolution_v2
    return convolution_internal(
  File "/home/avidbeam/.virtualenvs/TensorFlow_2/lib/python3.8/site-packages/tensorflow/python/ops/nn_ops.py", line 1257, in convolution_internal
    is_dilated_conv = any(i != 1 for i in dilations)
KeyboardInterrupt