2021-12-04 03:52:41,187 INFO    MainThread:344534 [internal.py:wandb_internal():87] W&B internal server running at pid: 344534, started at: 2021-12-04 03:52:41.187354
2021-12-04 03:52:41,188 DEBUG   HandlerThread:344534 [handler.py:handle_request():130] handle_request: check_version
2021-12-04 03:52:41,188 DEBUG   SenderThread:344534 [sender.py:send():238] send: header
2021-12-04 03:52:41,188 INFO    WriterThread:344534 [datastore.py:open_for_write():77] open: /media/avidbeam/workspace/Abdelrahman_Workspace/Project_Codes/Synergy/wandb/run-20211204_035240-3rzh9b42/run-3rzh9b42.wandb
2021-12-04 03:52:41,189 DEBUG   SenderThread:344534 [sender.py:send_request():252] send_request: check_version
2021-12-04 03:52:41,432 DEBUG   SenderThread:344534 [sender.py:send():238] send: run
2021-12-04 03:52:41,436 INFO    SenderThread:344534 [sender.py:_maybe_setup_resume():505] checking resume status for None/Synergy/3rzh9b42
2021-12-04 03:52:42,115 ERROR   SenderThread:344534 [internal_api.py:execute():144] 409 response executing GraphQL.
2021-12-04 03:52:42,116 ERROR   SenderThread:344534 [internal_api.py:execute():145] {"errors":[{"message":"Error 1062: Duplicate entry '577203-3rzh9b42' for key 'PRIMARY'","path":["upsertBucket"]}],"data":{"upsertBucket":null}}
2021-12-04 03:52:42,433 INFO    WriterThread:344534 [datastore.py:close():281] close: /media/avidbeam/workspace/Abdelrahman_Workspace/Project_Codes/Synergy/wandb/run-20211204_035240-3rzh9b42/run-3rzh9b42.wandb
2021-12-04 03:52:42,433 INFO    HandlerThread:344534 [handler.py:finish():731] shutting down handler
2021-12-04 03:52:42,434 ERROR   MainThread:344534 [internal.py:wandb_internal():158] Thread SenderThread:
Traceback (most recent call last):
  File "/home/avidbeam/.virtualenvs/TensorFlow_2/lib/python3.8/site-packages/wandb/apis/normalize.py", line 24, in wrapper
    return func(*args, **kwargs)
  File "/home/avidbeam/.virtualenvs/TensorFlow_2/lib/python3.8/site-packages/wandb/sdk/internal/internal_api.py", line 1298, in upsert_run
    response = self.gql(mutation, variable_values=variable_values, **kwargs)
  File "/home/avidbeam/.virtualenvs/TensorFlow_2/lib/python3.8/site-packages/wandb/sdk/lib/retry.py", line 102, in __call__
    result = self._call_fn(*args, **kwargs)
  File "/home/avidbeam/.virtualenvs/TensorFlow_2/lib/python3.8/site-packages/wandb/sdk/internal/internal_api.py", line 147, in execute
    six.reraise(*sys.exc_info())
  File "/home/avidbeam/.virtualenvs/TensorFlow_2/lib/python3.8/site-packages/six.py", line 719, in reraise
    raise value
  File "/home/avidbeam/.virtualenvs/TensorFlow_2/lib/python3.8/site-packages/wandb/sdk/internal/internal_api.py", line 141, in execute
    return self.client.execute(*args, **kwargs)
  File "/home/avidbeam/.virtualenvs/TensorFlow_2/lib/python3.8/site-packages/wandb/vendor/gql-0.2.0/gql/client.py", line 52, in execute
    result = self._get_result(document, *args, **kwargs)
  File "/home/avidbeam/.virtualenvs/TensorFlow_2/lib/python3.8/site-packages/wandb/vendor/gql-0.2.0/gql/client.py", line 60, in _get_result
    return self.transport.execute(document, *args, **kwargs)
  File "/home/avidbeam/.virtualenvs/TensorFlow_2/lib/python3.8/site-packages/wandb/vendor/gql-0.2.0/gql/transport/requests.py", line 39, in execute
    request.raise_for_status()
  File "/home/avidbeam/.virtualenvs/TensorFlow_2/lib/python3.8/site-packages/requests/models.py", line 953, in raise_for_status
    raise HTTPError(http_error_msg, response=self)
requests.exceptions.HTTPError: 409 Client Error: Conflict for url: https://api.wandb.ai/graphql

During handling of the above exception, another exception occurred:

Traceback (most recent call last):
  File "/home/avidbeam/.virtualenvs/TensorFlow_2/lib/python3.8/site-packages/wandb/sdk/internal/internal_util.py", line 52, in run
    self._run()
  File "/home/avidbeam/.virtualenvs/TensorFlow_2/lib/python3.8/site-packages/wandb/sdk/internal/internal_util.py", line 102, in _run
    self._process(record)
  File "/home/avidbeam/.virtualenvs/TensorFlow_2/lib/python3.8/site-packages/wandb/sdk/internal/internal.py", line 291, in _process
    self._sm.send(record)
  File "/home/avidbeam/.virtualenvs/TensorFlow_2/lib/python3.8/site-packages/wandb/sdk/internal/sender.py", line 240, in send
    send_handler(record)
  File "/home/avidbeam/.virtualenvs/TensorFlow_2/lib/python3.8/site-packages/wandb/sdk/internal/sender.py", line 708, in send_run
    self._init_run(run, config_value_dict)
  File "/home/avidbeam/.virtualenvs/TensorFlow_2/lib/python3.8/site-packages/wandb/sdk/internal/sender.py", line 732, in _init_run
    server_run, inserted = self._api.upsert_run(
  File "/home/avidbeam/.virtualenvs/TensorFlow_2/lib/python3.8/site-packages/wandb/apis/normalize.py", line 26, in wrapper
    raise CommError(err.response, err)
wandb.errors.CommError: <Response [409]>
2021-12-04 03:52:44,446 INFO    MainThread:344534 [internal.py:handle_exit():77] Internal process exited
