Epoch 1/100:
2021-12-02 19:16:23.186908: I tensorflow/stream_executor/cuda/cuda_dnn.cc:366] Loaded cuDNN version 8100
2021-12-02 19:16:23.923394: I tensorflow/stream_executor/cuda/cuda_blas.cc:1774] TensorFloat-32 will be used for the matrix multiplication. This will only be logged once.




















 201/3266 [>.............................] - ETA: 10:10 - train_loss: 2645.3010
Traceback (most recent call last):
  File "train.py", line 40, in <module>
    train(model, training_data_generator, validation_data_generator, 100,\
  File "/media/avidbeam/workspace/Abdelrahman_Workspace/Project_Codes/Synergy/utils/custom_fit.py", line 22, in train
    train_loss = train_batch(X_batch,\
  File "/media/avidbeam/workspace/Abdelrahman_Workspace/Project_Codes/Synergy/utils/custom_fit.py", line 56, in train_batch
    y_pred = model(X, training=True)
  File "/home/avidbeam/.virtualenvs/TensorFlow_2/lib/python3.8/site-packages/keras/utils/traceback_utils.py", line 64, in error_handler
    return fn(*args, **kwargs)
  File "/home/avidbeam/.virtualenvs/TensorFlow_2/lib/python3.8/site-packages/keras/engine/base_layer.py", line 1083, in __call__
    outputs = call_fn(inputs, *args, **kwargs)
  File "/home/avidbeam/.virtualenvs/TensorFlow_2/lib/python3.8/site-packages/keras/utils/traceback_utils.py", line 92, in error_handler
    return fn(*args, **kwargs)
  File "/media/avidbeam/workspace/Abdelrahman_Workspace/Project_Codes/Synergy/model/synergy.py", line 71, in call
    pose_3DMM_hat = self.decoder(Lr)
  File "/home/avidbeam/.virtualenvs/TensorFlow_2/lib/python3.8/site-packages/keras/utils/traceback_utils.py", line 64, in error_handler
    return fn(*args, **kwargs)
  File "/home/avidbeam/.virtualenvs/TensorFlow_2/lib/python3.8/site-packages/keras/engine/base_layer.py", line 1083, in __call__
    outputs = call_fn(inputs, *args, **kwargs)
  File "/home/avidbeam/.virtualenvs/TensorFlow_2/lib/python3.8/site-packages/keras/utils/traceback_utils.py", line 92, in error_handler
    return fn(*args, **kwargs)
  File "/home/avidbeam/.virtualenvs/TensorFlow_2/lib/python3.8/site-packages/keras/engine/functional.py", line 451, in call
    return self._run_internal_graph(
  File "/home/avidbeam/.virtualenvs/TensorFlow_2/lib/python3.8/site-packages/keras/engine/functional.py", line 589, in _run_internal_graph
    outputs = node.layer(*args, **kwargs)
  File "/home/avidbeam/.virtualenvs/TensorFlow_2/lib/python3.8/site-packages/keras/utils/traceback_utils.py", line 64, in error_handler
    return fn(*args, **kwargs)
  File "/home/avidbeam/.virtualenvs/TensorFlow_2/lib/python3.8/site-packages/keras/engine/base_layer.py", line 1063, in __call__
    input_spec.assert_input_compatibility(self.input_spec, inputs, self.name)
  File "/home/avidbeam/.virtualenvs/TensorFlow_2/lib/python3.8/site-packages/keras/engine/input_spec.py", line 154, in assert_input_compatibility
    def assert_input_compatibility(input_spec, inputs, layer_name):
KeyboardInterrupt